[2024-06-03T23:46:55.225-0500] {local_task_job_runner.py:120} INFO - ::group::Pre task execution logs
[2024-06-03T23:46:55.308-0500] {taskinstance.py:2076} INFO - Dependencies all met for dep_context=non-requeueable deps ti=<TaskInstance: python_pipeline.group_by_region manual__2024-06-04T04:46:44.330829+00:00 [queued]>
[2024-06-03T23:46:55.314-0500] {taskinstance.py:2076} INFO - Dependencies all met for dep_context=requeueable deps ti=<TaskInstance: python_pipeline.group_by_region manual__2024-06-04T04:46:44.330829+00:00 [queued]>
[2024-06-03T23:46:55.314-0500] {taskinstance.py:2306} INFO - Starting attempt 1 of 1
[2024-06-03T23:46:55.334-0500] {taskinstance.py:2330} INFO - Executing <Task(PythonOperator): group_by_region> on 2024-06-04 04:46:44.330829+00:00
[2024-06-03T23:46:55.338-0500] {standard_task_runner.py:63} INFO - Started process 50563 to run task
[2024-06-03T23:46:55.341-0500] {standard_task_runner.py:90} INFO - Running: ['airflow', 'tasks', 'run', 'python_pipeline', 'group_by_region', 'manual__2024-06-04T04:46:44.330829+00:00', '--job-id', '331', '--raw', '--subdir', 'DAGS_FOLDER/data_cleaning.py', '--cfg-path', '/tmp/tmpja8iv0it']
[2024-06-03T23:46:55.343-0500] {standard_task_runner.py:91} INFO - Job 331: Subtask group_by_region
[2024-06-03T23:46:55.379-0500] {task_command.py:426} INFO - Running <TaskInstance: python_pipeline.group_by_region manual__2024-06-04T04:46:44.330829+00:00 [running]> on host diallo
[2024-06-03T23:46:55.456-0500] {taskinstance.py:2648} INFO - Exporting env vars: AIRFLOW_CTX_DAG_OWNER='Diallo' AIRFLOW_CTX_DAG_ID='python_pipeline' AIRFLOW_CTX_TASK_ID='group_by_region' AIRFLOW_CTX_EXECUTION_DATE='2024-06-04T04:46:44.330829+00:00' AIRFLOW_CTX_TRY_NUMBER='1' AIRFLOW_CTX_DAG_RUN_ID='manual__2024-06-04T04:46:44.330829+00:00'
[2024-06-03T23:46:55.457-0500] {taskinstance.py:430} INFO - ::endgroup::
[2024-06-03T23:46:55.470-0500] {data_cleaning.py:66} INFO - Pulling JSON data from XCom
[2024-06-03T23:46:55.474-0500] {data_cleaning.py:86} ERROR - Error in group_by_region task
Traceback (most recent call last):
  File "/home/diallo/airflow/dags/data_cleaning.py", line 71, in group_by_region
    raise ValueError("No data found in XCom for task_id 'clean_daka'")
ValueError: No data found in XCom for task_id 'clean_daka'
[2024-06-03T23:46:55.475-0500] {taskinstance.py:441} INFO - ::group::Post task execution logs
[2024-06-03T23:46:55.475-0500] {taskinstance.py:2905} ERROR - Task failed with exception
Traceback (most recent call last):
  File "/home/diallo/Documents/workspace/Python/AirFlowProjects/AirFlow01/venv/lib/python3.10/site-packages/airflow/models/taskinstance.py", line 465, in _execute_task
    result = _execute_callable(context=context, **execute_callable_kwargs)
  File "/home/diallo/Documents/workspace/Python/AirFlowProjects/AirFlow01/venv/lib/python3.10/site-packages/airflow/models/taskinstance.py", line 432, in _execute_callable
    return execute_callable(context=context, **execute_callable_kwargs)
  File "/home/diallo/Documents/workspace/Python/AirFlowProjects/AirFlow01/venv/lib/python3.10/site-packages/airflow/models/baseoperator.py", line 400, in wrapper
    return func(self, *args, **kwargs)
  File "/home/diallo/Documents/workspace/Python/AirFlowProjects/AirFlow01/venv/lib/python3.10/site-packages/airflow/operators/python.py", line 235, in execute
    return_value = self.execute_callable()
  File "/home/diallo/Documents/workspace/Python/AirFlowProjects/AirFlow01/venv/lib/python3.10/site-packages/airflow/operators/python.py", line 252, in execute_callable
    return self.python_callable(*self.op_args, **self.op_kwargs)
  File "/home/diallo/airflow/dags/data_cleaning.py", line 87, in group_by_region
    raise e
  File "/home/diallo/airflow/dags/data_cleaning.py", line 71, in group_by_region
    raise ValueError("No data found in XCom for task_id 'clean_daka'")
ValueError: No data found in XCom for task_id 'clean_daka'
[2024-06-03T23:46:55.479-0500] {taskinstance.py:1206} INFO - Marking task as FAILED. dag_id=python_pipeline, task_id=group_by_region, run_id=manual__2024-06-04T04:46:44.330829+00:00, execution_date=20240604T044644, start_date=20240604T044655, end_date=20240604T044655
[2024-06-03T23:46:55.493-0500] {standard_task_runner.py:110} ERROR - Failed to execute job 331 for task group_by_region (No data found in XCom for task_id 'clean_daka'; 50563)
[2024-06-03T23:46:55.514-0500] {local_task_job_runner.py:240} INFO - Task exited with return code 1
[2024-06-03T23:46:55.543-0500] {taskinstance.py:3498} INFO - 0 downstream tasks scheduled from follow-on schedule check
[2024-06-03T23:46:55.543-0500] {local_task_job_runner.py:222} INFO - ::endgroup::
